Workbook
Name Ccy: #REF!
Name Conv: #REF!
Name Discount_Rate: #REF!
Name IQ_CH: 110000
Name IQ_CQ: 5000
Name IQ_CY: 10000
Name IQ_DAILY: 500000
Name IQ_FH: 100000
Name IQ_FQ: 500
Name IQ_FY: 1000
Name IQ_LTM: 2000
Name IQ_MONTH: 15000
Name IQ_NTM: 6000
Name IQ_WEEK: 50000
Name IQ_YTD: 3000
Name QFour: #REF!
Name Scenario: #REF!
Name SharePrice: #REF!
Name Tax: #REF!
Name Tax_Rate: #REF!
Name WACC: #REF!

Sheet Cover
C3: European Call Option Valuation | AAPL
C11: Cross-Method Pricing Analysis
C12: Black-Scholes-Merton · Binomial Tree · Monte Carlo

Sheet Important Comments
C3: Editure Limited | Important Comments
C5: =Cover!C5 -> 0
A7: x | C7: Overview
B9: x | C9: Key Assumptions (Due to Lack of Information in CIM)
C11: Assumption | D11: Value | E11: Commentary
C12: Comparable Company Analysis | D12: n.a. | E12: This method was not relied upon. Please see "Comps" tab for detailed explanation.
C13: Model Date | D13: 40999 | E13: Given that the CIM incorporates financials for Q1 2012, the model date was assumed to be March 31, 2012.
C14: General Model Assumptions | D14: Various | E14: Please see comments in specific cells throughout the model for explanations of minor assumptions.
C15: "Assumptions" Tab | D15: Various | E15: Please see additional commentary on the right side of the "Assumptions" tab that explains the though process behind assumptions
C16: Q4 2012E Allocation | D16: =3000/6892 -> 0.43528729 | E16: Given the model date of March 31, the valuation needed to include Q4 of 2012. However, there was no quarterly information available in the CIM except for 2013P EBITDA projections on Pg. 63, which indicated most earnings are generated in quarters 3 and 4 due to seasonality. As a result, Q4 2013P's EBITDA as a % of the total year's EBITDA was used as a proxy to allocate 2012E's yearly figures to Q4 of 2012. This method was deemed to be the best and only option, as the alternative was to not include Q4 numbers in the valuation at all, which was we believed would have been more inaccurate.
C17: Depreciation | D17: Equal to CapEx | E17: Since no depreciation information was provided in the CIM, depreciation was set equal to CapEx so that 1) FCF was not understated because of not adding back depreciation, 2) the tax saving of depreciation could be accounted for, and 3) depreciation and CapEx could be equal in the terminal year.
C18: Exit Multiple | D18: n.a. | E18: This method was completed for illustration and completion purposes only as it was not relied upon. There is no way to accurately estimate Editure's exit multiple given that comps were not public in 2012 and there is no trading history.
C19: Debt / Equity Split | D19: 0 | E19: Debt weighting was set at 0% as there was no long-term debt on balance sheet (did not count "Other Creditors" as debt). Additionally, there is no accurate way to estimate cost of debt without the interest rates on debts and/or interest expense on the income statement (could have approximated a debt rating). Due to this lack of information in the financials, it was more accurate to assume "Other Creditors" was not included in debt instead of assuming an arbitrary cost of debt.
C20: Beta | D20: 1.25 | E20: Given that 2012 public comparable companies were unavailable and that Editure itself is a private company, there were no public options for calculating beta. As a result, the only option was to reasonably estimate beta according to our experience in the finance industry. We believed that for a technology company, specifically one in the growing education technology space, a beta of 1.25 was a reasonable estimate. This represents its relatively higher volatility compared to the overall market. Additionally, out of the three comparable companies, only one (Learning Technologies Group) has a beta today, which is 1.33. Given that the outlook and performance of the technology sector is not the same today as it was in 2012, we used this figure as a sense check and determined it was reasonable to use a slightly lower figure of 1.25 for this valuation.
A23: x | B23: x

Sheet Summary
C3: AAPL $250 Call Option Valuation | Summary
C6: Base Case Valuation (Implied Vol)
C8: Method | D8: Theoretical Value | E8: Volatility Used
C9: Black-Scholes-Merton Model | D9: 22.63 | E9: ='Option Monitor'!F7/100 -> 0.31072491
C10: Binomial Tree | D10: 22.64 | E10: ='Option Monitor'!F7/100 -> 0.31072491
C11: Monte Carlo | D11: ='Monte Carlo'!K25 -> 22.594179 | E11: ='Option Monitor'!F7/100 -> 0.31072491
C13: Alternative Case Cross-Check (Historical Vol)
C15: Method | D15: Theoretical Value | E15: Volatility Used
C16: Black-Scholes-Merton Model | D16: 16.74 | E16: ='Historical Prices'!F9 -> 0.22560599
C17: Binomial Tree | D17: 16.76 | E17: ='Historical Prices'!F9 -> 0.22560599
C18: Monte Carlo | D18: ='Monte Carlo'!K26 -> 16.711456 | E18: ='Historical Prices'!F9 -> 0.22560599
C20: Observed Bloomberg Market Price Midpoint (IV = 31.07%) | D20: =('Option Monitor'!C7+'Option Monitor'!D7)/2 -> 22.650001

Sheet Models>>

Sheet _CIQHiddenCacheSheet
